Workbook

Sheet MITRA (REFERENSI)
A1: Nama Lengkap | B1: Posisi | C1: Status Seleksi (1=Terpilih, 2=Tidak Terpilih) | D1: Posisi Daftar | E1: Alamat Detail | F1: Alamat Prov | G1: Alamat Kab | H1: Alamat Kec | I1: Alamat Desa | J1: Tempat, Tanggal Lahir (Umur)* | K1: Jenis Kelamin | L1: Pendidikan | M1: Pekerjaan | N1: Deskripsi Pekerjaan Lain | O1: No Telp | P1: SOBAT ID | Q1: Email | R1: Nilai Ujian | S1: Waktu Mulai | T1: Waktu Submit | U1: Durasi (menit) | V1: Remedial (kali) | W1: Status PI | X1: Waktu PI | Y1: Profesi | Z1: Alamat
A2: Abdillah | B2: Mitra Pendataan | C2: Diterima | D2: Mitra Pendataan | E2: Jl.cip pulo maja rt 06 rw 11 | F2: 31 | G2: 72 | H2: 060 | I2: 005 | J2: TANAH DATAR, 12 Juli 1976 (50) | K2: Lk | L2: Tamat SMA/Sederajat | M2: Wiraswasta | O2: +62 813-1991-4129 | P2: 317222100443 | Q2: aabdillah721@gmail.com | R2: 86.67 | S2: 2025-11-21 15:15:34 | T2: 2025-11-21 16:09:46 | U2: 54.2 | V2: 0 | W2: Disetujui | X2: 20251205 17:10:39 | Y2: =IF(N2="",M2,N2) -> Wiraswasta | Z2: =VLOOKUP(H2,'[1]KELAS (REF) 1080'!$Q:$R,2,FALSE) -> #REF!
A3: ABDULLAH FANSURI | B3: Mitra Pendataan | C3: Diterima | D3: Mitra Pendataan | E3: Ko.pisangan RT 008 RW 005 Kel.penggilingan | F3: 31 | G3: 72 | H3: 080 | I3: 002 | J3: , 26 September 1978 (48) | K3: Lk | L3: Tamat SMA/Sederajat | M3: Lainnya | N3: Mitra bps | O3: +62 089-8903-1373 | P3: 317222010003 | Q3: fansuriabdullah9@gmail.com | R3: 93.33 | S3: 2025-11-20 11:57:32 | T3: 2025-11-20 12:27:05 | U3: 29.55 | V3: 0 | W3: Disetujui | X3: 20251204 09:56:36 | Y3: =IF(N3="",M3,N3) -> Mitra bps | Z3: =VLOOKUP(H3,'[1]KELAS (REF) 1080'!$Q:$R,2,FALSE) -> #REF!
A4: Abdurrahman Farisy | B4: Mitra (Pendataan dan Pengolahan) | C4: Diterima | D4: Mitra (Pendataan dan Pengolahan) | E4: Jl.Kebon Nanas Selatan II | F4: 31 | G4: 72 | H4: 060 | I4: 002 | J4: , 19 Juli 2006 (20) | K4: Lk | L4: Tamat SMA/Sederajat | M4: Kader PKK / Karang Taruna / Kader Lainnya | O4: +62 859-5807-2007 | P4: 317225050087 | Q4: ghostfather101@gmail.com | R4: 100.00 | S4: 2025-11-24 07:26:51 | T4: 2025-11-24 07:36:32 | U4: 9.6833333 | V4: 0 | W4: Disetujui | X4: 20251204 12:51:48 | Y4: =IF(N4="",M4,N4) -> Kader PKK / Karang Taruna / Kader Lainnya | Z4: =VLOOKUP(H4,'[1]KELAS (REF) 1080'!$Q:$R,2,FALSE) -> #REF!
A5: Achmad As Adi | B5: Mitra (Pendataan dan Pengolahan) | C5: Diterima | D5: Mitra (Pendataan dan Pengolahan) | E5: Kp.Pisangan Rt 001/04 no.20 | F5: 31 | G5: 72 | H5: 080 | I5: 002 | J5: JAKARTA BARAT, 09 Juli 1970 (56) | K5: Lk | L5: Tamat SMA/Sederajat | M5: Wiraswasta | O5: +62 812-8444-8884 | P5: 317222010093 | Q5: achmadasadi001@gmail.com | R5: 93.33 | S5: 2025-11-20 13:01:57 | T5: 2025-11-20 13:23:36 | U5: 21.65 | V5: 0 | W5: Disetujui | X5: 20251204 11:35:39 | Y5: =IF(N5="",M5,N5) -> Wiraswasta | Z5: =VLOOKUP(H5,'[1]KELAS (REF) 1080'!$Q:$R,2,FALSE) -> #REF!
A6: ACHMAD RIFAL | B6: Mitra (Pendataan dan Pengolahan) | C6: Diterima | D6: Mitra (Pendataan dan Pengolahan) | E6: jl. pahlawan revolusi .no26AB RT001/RW007 | F6: 31 | G6: 72 | H6: 070 | I6: 001 | J6: JAKARTA TIMUR, 19 Agustus 1991 (35) | K6: Lk | L6: Tamat D4/S1 | M6: Lainnya | N6: karyawan swasta | O6: +62 821-1030-6471 | P6: 317222092137 | Q6: riffallachmad@gmail.com | R6: 86.67 | S6: 2025-11-20 15:00:14 | T6: 2025-11-20 15:25:10 | U6: 24.933333 | V6: 0 | W6: Disetujui | X6: 20251204 21:09:05 | Y6: =IF(N6="",M6,N6) -> karyawan swasta | Z6: =VLOOKUP(H6,'[1]KELAS (REF) 1080'!$Q:$R,2,FALSE) -> #REF!
A7: Achmad zaidanul haq | B7: Mitra (Pendataan dan Pengolahan) | C7: Diterima | D7: Mitra (Pendataan dan Pengolahan) | E7: Jalan gardu NO:03 RT. 009/03 | F7: 31 | G7: 72 | H7: 050 | I7: 001 | J7: JAKARTA TIMUR, 17 Januari 2000 (25) | K7: Lk | L7: Tamat SMA/Sederajat | M7: Lainnya | N7: Wirausaha | O7: +62 856-9123-4570 | P7: 317222010240 | Q7: achmadzaidan.haq@gmail.com | R7: 93.33 | S7: 2025-11-20 13:38:33 | T7: 2025-11-20 13:49:51 | U7: 11.3 | V7: 0 | W7: Disetujui | X7: 20251204 17:13:29 | Y7: =IF(N7="",M7,N7) -> Wirausaha | Z7: =VLOOKUP(H7,'[1]KELAS (REF) 1080'!$Q:$R,2,FALSE) -> #REF!
A8: Achyani | B8: Mitra (Pendataan dan Pengolahan) | C8: Diterima | D8: Mitra (Pendataan dan Pengolahan) | E8: Jln perintis kemerdekaan | F8: 31 | G8: 72 | H8: 090 | I8: 007 | J8: JAKARTA TIMUR, 14 Januari 1977 (48) | K8: Pr | L8: Tamat SMA/Sederajat | M8: Kader PKK / Karang Taruna / Kader Lainnya | O8: +62 812-9217-0234 | P8: 317225050032 | Q8: achyaniatang@gmail.com | R8: 86.67 | S8: 2025-11-19 09:01:31 | T8: 2025-11-19 09:51:42 | U8: 50.183333 | V8: 0 | W8: Disetujui | X8: 20251204 17:27:54 | Y8: =IF(N8="",M8,N8) -> Kader PKK / Karang Taruna / Kader Lainnya | Z8: =VLOOKUP(H8,'[1]KELAS (REF) 1080'!$Q:$R,2,FALSE) -> #REF!
A9: Achyar Ramadhan | B9: Mitra (Pendataan dan Pengolahan) | C9: Diterima | D9: Mitra (Pendataan dan Pengolahan) | E9: Jalan pemuda 2 no.19 | F9: 31 | G9: 72 | H9: 090 | I9: 005 | J9: JAKARTA TIMUR, 04 Juni 1972 (54) | K9: Lk | L9: Tamat SMA/Sederajat | M9: Wiraswasta | O9: +62 813-1958-9181 | P9: 317222010183 | Q9: achyarramadhan9@gmail.com | R9: 86.67 | S9: 2025-11-20 12:32:01 | T9: 2025-11-20 12:53:29 | U9: 21.466667 | V9: 0 | W9: Disetujui | X9: 20251205 15:18:57 | Y9: =IF(N9="",M9,N9) -> Wiraswasta | Z9: =VLOOKUP(H9,'[1]KELAS (REF) 1080'!$Q:$R,2,FALSE) -> #REF!
A10: Ade misfah juned | B10: Mitra (Pendataan dan Pengolahan) | C10: Diterima | D10: Mitra (Pendataan dan Pengolahan) | E10: Jalan pisangan baru utara rt 09 rw 013 no 14 matraman | F10: 31 | G10: 72 | H10: 100 | I10: 003 | J10: JAKARTA TIMUR, 12 Agustus 1976 (50) | K10: Pr | L10: Tamat SMA/Sederajat | M10: Kader PKK / Karang Taruna / Kader Lainnya | O10: +62 878-8157-8611 | P10: 317222090093 | Q10: ademisfah08@gmail.com | R10: 90.00 | S10: 2025-11-21 09:01:32 | T10: 2025-11-21 09:23:50 | U10: 22.3 | V10: 0 | W10: Disetujui | X10: 20251204 11:17:54 | Y10: =IF(N10="",M10,N10) -> Kader PKK / Karang Taruna / Kader Lainnya | Z10: =VLOOKUP(H10,'[1]KELAS (REF) 1080'!$Q:$R,2,FALSE) -> #REF!
A11: Ade suhanah | B11: Mitra Pendataan | C11: Diterima | D11: Mitra Pendataan | E11: Jalan kebon pala 1 RT 006 RW 007 NO. 39 | F11: 31 | G11: 72 | H11: 040 | I11: 004 | J11: JAKARTA UTARA, 16 Juni 1975 (51) | K11: Pr | L11: Tamat D4/S1 | M11: Mengurus Rumah Tangga | O11: +62 857-1053-2827 | P11: 317222050020 | Q11: Adesuhanah78@gmail.com | R11: 83.33 | S11: 2025-11-24 15:09:06 | T11: 2025-11-24 15:34:37 | U11: 25.516667 | V11: 0 | W11: Disetujui | X11: 20251205 16:47:06 | Y11: =IF(N11="",M11,N11) -> Mengurus Rumah Tangga | Z11: =VLOOKUP(H11,'[1]KELAS (REF) 1080'!$Q:$R,2,FALSE) -> #REF!
A12: Ade Yeni Nurhayati | B12: Mitra (Pendataan dan Pengolahan) | C12: Diterima | D12: Mitra (Pendataan dan Pengolahan) | E12: Jl. Nanas1, gg. Flamboyan 5 rt 004/003 | F12: 31 | G12: 72 | H12: 100 | I12: 005 | J12: , 15 April 1989 (37) | K12: Pr | L12: Tamat SMA/Sederajat | M12: Kader PKK / Karang Taruna / Kader Lainnya | O12: +62 085-7103-13841 | P12: 317222090671 | Q12: adeyeninurhayati4@gmail.com | R12: 96.67 | S12: 2025-11-21 15:02:35 | T12: 2025-11-21 15:25:41 | U12: 23.1 | V12: 0 | W12: Disetujui | X12: 20251204 11:57:40 | Y12: =IF(N12="",M12,N12) -> Kader PKK / Karang Taruna / Kader Lainnya | Z12: =VLOOKUP(H12,'[1]KELAS (REF) 1080'!$Q:$R,2,FALSE) -> #REF!
A13: Adil Fagli | B13: Mitra (Pendataan dan Pengolahan) | C13: Diterima | D13: Mitra (Pendataan dan Pengolahan) | E13: Kp Rawadas No 162 RT 001 RW 03 | F13: 31 | G13: 72 | H13: 070 | I13: 004 | J13: JAKARTA TIMUR, 04 Juli 1989 (37) | K13: Lk | L13: Tamat SMA/Sederajat | M13: Wiraswasta | O13: +62 821-1397-6914 | P13: 317222010129 | Q13: adil700c@gmail.com | R13: 86.67 | S13: 2025-11-21 09:00:56 | T13: 2025-11-21 09:20:36 | U13: 19.666667 | V13: 0 | W13: Disetujui | X13: 20251204 18:29:45 | Y13: =IF(N13="",M13,N13) -> Wiraswasta | Z13: =VLOOKUP(H13,'[1]KELAS (REF) 1080'!$Q:$R,2,FALSE) -> #REF!
A14: Adinda Maharani Salsabila | B14: Mitra (Pendataan dan Pengolahan) | C14: Diterima | D14: Mitra (Pendataan dan Pengolahan) | E14: Klender | F14: 31 | G14: 72 | H14: 070 | I14: 007 | J14: JAKARTA UTARA, 16 April 2000 (26) | K14: Pr | L14: Tamat D4/S1 | M14: Wiraswasta | O14: +62 819-9534-3604 | P14: 317223110140 | Q14: adindamaharanisalsabila845@gmail.com | R14: 93.33 | S14: 2025-11-18 15:17:51 | T14: 2025-11-18 15:31:48 | U14: 13.95 | V14: 0 | W14: Disetujui | X14: 20251208 10:54:03 | Y14: =IF(N14="",M14,N14) -> Wiraswasta | Z14: =VLOOKUP(H14,'[1]KELAS (REF) 1080'!$Q:$R,2,FALSE) -> #REF!
A15: Afi Herprabawati | B15: Mitra (Pendataan dan Pengolahan) | C15: Diterima | D15: Mitra (Pendataan dan Pengolahan) | E15: Jl flamboyan no 16 rt 1 rw 18 | F15: 31 | G15: 72 | H15: 070 | I15: 007 | J15: MALANG, 03 April 1970 (56) | K15: Pr | L15: Tamat D4/S1 | M15: Mengurus Rumah Tangga | O15: +62 081-1815-895 | P15: 317223070004 | Q15: afiherprabawati@gmail.com | R15: 93.33 | S15: 2025-11-19 15:04:02 | T15: 2025-11-19 15:21:15 | U15: 17.216667 | V15: 0 | W15: Disetujui | X15: 20251205 14:59:25 | Y15: =IF(N15="",M15,N15) -> Mengurus Rumah Tangga | Z15: =VLOOKUP(H15,'[1]KELAS (REF) 1080'!$Q:$R,2,FALSE) -> #REF!
A16: Agnes Ristriyanti | B16: Mitra (Pendataan dan Pengolahan) | C16: Diterima | D16: Mitra (Pendataan dan Pengolahan) | E16: Jl rawadas rt008 rw003 no 25 | F16: 31 | G16: 72 | H16: 070 | I16: 004 | J16: JAKARTA TIMUR, 13 Agustus 1976 (50) | K16: Pr | L16: Tamat SMA/Sederajat | M16: Mengurus Rumah Tangga | O16: +62 813-8547-5188 | P16: 317222020091 | Q16: agnesristrianti4@gmail.com | R16: 96.67 | S16: 2025-11-21 11:00:09 | T16: 2025-11-21 11:09:24 | U16: 9.25 | V16: 0 | W16: Disetujui | X16: 20251204 10:30:11 | Y16: =IF(N16="",M16,N16) -> Mengurus Rumah Tangga | Z16: =VLOOKUP(H16,'[1]KELAS (REF) 1080'!$Q:$R,2,FALSE) -> #REF!
A17: Agus amirullah | B17: Mitra (Pendataan dan Pengolahan) | C17: Diterima | D17: Mitra (Pendataan dan Pengolahan) | E17: Jln rambutan rt 03/010 kel baru | F17: 31 | G17: 72 | H17: 010 | I17: 003 | J17: JAKARTA TIMUR, 30 Agustus 1972 (54) | K17: Lk | L17: Tamat SMA/Sederajat | M17: Wiraswasta | O17: +62 852-8533-7057 | P17: 317222090587 | Q17: agusamirullah7@gmail.com | R17: 86.67 | S17: 2025-11-21 15:00:33 | T17: 2025-11-21 15:30:15 | U17: 29.7 | V17: 0 | W17: Disetujui | X17: 20251204 21:44:09 | Y17: =IF(N17="",M17,N17) -> Wiraswasta | Z17: =VLOOKUP(H17,'[1]KELAS (REF) 1080'!$Q:$R,2,FALSE) -> #REF!
A18: AGUSTIN RETNOWATI | B18: Mitra Pendataan | C18: Diterima | D18: Mitra Pendataan | E18: Jl. Kayumanis I Lama No. 16 Rt 004 Rw 008 | F18: 31 | G18: 72 | H18: 100 | I18: 002 | J18: , 05 Agustus 1970 (56) | K18: Pr | L18: Tamat SMA/Sederajat | M18: Kader PKK / Karang Taruna / Kader Lainnya | O18: +62 838-9143-7069 | P18: 317222090323 | Q18: enoagustin5870@gmail.com | R18: 86.67 | S18: 2025-11-21 15:19:07 | T18: 2025-11-21 16:08:46 | U18: 49.65 | V18: 0 | W18: Disetujui | X18: 20251204 11:44:12 | Y18: =IF(N18="",M18,N18) -> Kader PKK / Karang Taruna / Kader Lainnya | Z18: =VLOOKUP(H18,'[1]KELAS (REF) 1080'!$Q:$R,2,FALSE) -> #REF!
A19: Agustina | B19: Mitra (Pendataan dan Pengolahan) | C19: Diterima | D19: Mitra (Pendataan dan Pengolahan) | E19: Jln kelapa gading 1 rt.004 rw.001 no.3 | F19: 31 | G19: 72 | H19: 050 | I19: 005 | J19: JAKARTA TIMUR, 04 Agustus 1973 (53) | K19: Pr | L19: Tamat SMA/Sederajat | M19: Lainnya | N19: Ketua RT | O19: +62 838-6672-0365 | P19: 317222010344 | Q19: agusssstina8@gmail.com | R19: 90.00 | S19: 2025-11-21 11:10:43 | T19: 2025-11-21 11:34:41 | U19: 23.966667 | V19: 0 | W19: Disetujui | X19: 20251204 23:09:42 | Y19: =IF(N19="",M19,N19) -> Ketua RT | Z19: =VLOOKUP(H19,'[1]KELAS (REF) 1080'!$Q:$R,2,FALSE) -> #REF!
A20: Ahmad Wildani | B20: Mitra (Pendataan dan Pengolahan) | C20: Diterima | D20: Mitra (Pendataan dan Pengolahan) | E20: Jl. Kayu Putih Tengah IV E No. 14 RT. 003/ RW. 007 | F20: 31 | G20: 72 | H20: 090 | I20: 007 | J20: JAKARTA TIMUR, 24 Januari 1989 (36) | K20: Lk | L20: Tamat D4/S1 | M20: Wiraswasta | O20: +62 813-8014-1763 | P20: 317225050048 | Q20: ahmadwildani2401@gmail.com | R20: 96.67 | S20: 2025-11-20 13:08:05 | T20: 2025-11-20 13:39:05 | U20: 31 | V20: 0 | W20: Disetujui | X20: 20251204 17:21:47 | Y20: =IF(N20="",M20,N20) -> Wiraswasta | Z20: =VLOOKUP(H20,'[1]KELAS (REF) 1080'!$Q:$R,2,FALSE) -> #REF!
A21: Aisyah | B21: Mitra (Pendataan dan Pengolahan) | C21: Diterima | D21: Mitra (Pendataan dan Pengolahan) | E21: Jl. Rawadas rt009/03 | F21: 31 | G21: 72 | H21: 070 | I21: 004 | J21: , 01 Juni 1979 (47) | K21: Pr | L21: Tamat D4/S1 | M21: Wiraswasta | O21: +62 081-2820-34640 | P21: 317222020085 | Q21: aisyahmikoza@gmail.com | R21: 93.33 | S21: 2025-11-21 09:16:15 | T21: 2025-11-21 09:30:39 | U21: 14.4 | V21: 0 | W21: Disetujui | X21: 20251204 10:15:40 | Y21: =IF(N21="",M21,N21) -> Wiraswasta | Z21: =VLOOKUP(H21,'[1]KELAS (REF) 1080'!$Q:$R,2,FALSE) -> #REF!
A22: AJI SEPTIANTO | B22: Mitra (Pendataan dan Pengolahan) | C22: Diterima | D22: Mitra (Pendataan dan Pengolahan) | E22: jalan kayumas utara rt 007 rw 009 | F22: 31 | G22: 72 | H22: 090 | I22: 007 | J22: JAKARTA TIMUR, 27 September 2002 (24) | K22: Lk | L22: Tamat SMA/Sederajat | M22: Lainnya | N22: - | O22: +62 855-9115-8986 | P22: 317225050059 | Q22: ajiseptianto8@gmail.com | R22: 90.00 | S22: 2025-11-19 15:00:28 | T22: 2025-11-19 15:23:34 | U22: 23.1 | V22: 0 | W22: Disetujui | X22: 20251204 16:03:19 | Y22: =IF(N22="",M22,N22) -> - | Z22: =VLOOKUP(H22,'[1]KELAS (REF) 1080'!$Q:$R,2,FALSE) -> #REF!
A23: alffito deannofal | B23: Mitra (Pendataan dan Pengolahan) | C23: Diterima | D23: Mitra (Pendataan dan Pengolahan) | E23: jalan rawa kuning RT 007 RW 016 GG Abadi | F23: 31 | G23: 72 | H23: 080 | I23: 003 | J23: JAKARTA TIMUR, 15 Juni 2004 (22) | K23: Lk | L23: Tamat SMA/Sederajat | M23: Pelajar / Mahasiswa | O23: +62 858-8089-2684 | P23: 317222040075 | Q23: alffito15@gmail.com | R23: 90.00 | S23: 2025-11-21 15:00:56 | T23: 2025-11-21 15:25:49 | U23: 24.883333 | V23: 0 | W23: Disetujui | X23: 20251204 14:16:19 | Y23: =IF(N23="",M23,N23) -> Pelajar / Mahasiswa | Z23: =VLOOKUP(H23,'[1]KELAS (REF) 1080'!$Q:$R,2,FALSE) -> #REF!
A24: Alvian Rainda Putra | B24: Mitra (Pendataan dan Pengolahan) | C24: Diterima | D24: Mitra (Pendataan dan Pengolahan) | E24: Jl. Kebon Nanas II | F24: 31 | G24: 72 | H24: 060 | I24: 002 | J24: JAKARTA TIMUR, 27 September 1993 (33) | K24: Lk | L24: Tamat SMA/Sederajat | M24: Lainnya | N24: Belum Bekerja | O24: +62 813-8138-9910 | P24: 317222091606 | Q24: alvian.rp@gmail.com | R24: 96.67 | S24: 2025-11-21 13:09:09 | T24: 2025-11-21 13:20:22 | U24: 11.216667 | V24: 0 | W24: Disetujui | X24: 20251204 12:23:23 | Y24: =IF(N24="",M24,N24) -> Belum Bekerja | Z24: =VLOOKUP(H24,'[1]KELAS (REF) 1080'!$Q:$R,2,FALSE) -> #REF!
A25: Alya Ega Fatihah | B25: Mitra (Pendataan dan Pengolahan) | C25: Diterima | D25: Mitra (Pendataan dan Pengolahan) | E25: Jl. Mandala V No.17B rt 006/09 | F25: 31 | G25: 72 | H25: 050 | I25: 006 | J25: JAKARTA TIMUR, 07 Juni 1999 (27) | K25: Pr | L25: Tamat D4/S1 | M25: Kader PKK / Karang Taruna / Kader Lainnya | O25: +62 895-3595-50099 | P25: 317225050003 | Q25: aalyaef@gmail.com | R25: 90.00 | S25: 2025-11-24 15:12:13 | T25: 2025-11-24 15:38:20 | U25: 26.116667 | V25: 0 | W25: Disetujui | X25: 20251208 16:13:45 | Y25: =IF(N25="",M25,N25) -> Kader PKK / Karang Taruna / Kader Lainnya | Z25: =VLOOKUP(H25,'[1]KELAS (REF) 1080'!$Q:$R,2,FALSE) -> #REF!
A26: Amanda Imaniar Octaviyanti | B26: Mitra (Pendataan dan Pengolahan) | C26: Diterima | D26: Mitra (Pendataan dan Pengolahan) | E26: JALAN NUSA I RT 009 RW 003 | F26: 31 | G26: 72 | H26: 050 | I26: 005 | J26: , 14 Oktober 1990 (36) | K26: Pr | L26: Tamat SMA/Sederajat | M26: Mengurus Rumah Tangga | O26: +62 859-0174-2707 | P26: 321522091579 | Q26: Amandaimaniaroctaviyanti191@gmail.com | R26: 96.67 | S26: 2025-11-20 13:56:43 | T26: 2025-11-20 14:42:23 | U26: 45.666667 | V26: 0 | W26: Disetujui | X26: 20251204 21:32:22 | Y26: =IF(N26="",M26,N26) -> Mengurus Rumah Tangga | Z26: =VLOOKUP(H26,'[1]KELAS (REF) 1080'!$Q:$R,2,FALSE) -> #REF!
A27: Amanda Nur Pratiwi | B27: Mitra (Pendataan dan Pengolahan) | C27: Diterima | D27: Mitra (Pendataan dan Pengolahan) | E27: Jl. Kayumanis IX RT 012 RW 09 NO 26 | F27: 31 | G27: 72 | H27: 100 | I27: 004 | J27: JAKARTA TIMUR, 12 Maret 2002 (24) | K27: Pr | L27: Tamat SMA/Sederajat | M27: Lainnya | N27: Mencari kerja | O27: +62 897-8304-560 | P27: 317222090625 | Q27: amandanurp050516@gmail.com | R27: 86.67 | S27: 2025-11-20 15:05:43 | T27: 2025-11-20 16:05:44 | U27: 60.016667 | V27: 0 | W27: Disetujui | X27: 20251204 09:26:47 | Y27: =IF(N27="",M27,N27) -> Mencari kerja | Z27: =VLOOKUP(H27,'[1]KELAS (REF) 1080'!$Q:$R,2,FALSE) -> #REF!
A28: Amanda Swari Prasepti | B28: Mitra (Pendataan dan Pengolahan) | C28: Diterima | D28: Mitra (Pendataan dan Pengolahan) | E28: Jl Satria, Gg. Swadaya No.45 RT 001/ RW 03 | F28: 31 | G28: 72 | H28: 080 | I28: 004 | J28: , 06 September 1994 (32) | K28: Pr | L28: Tamat D4/S1 | M28: Mengurus Rumah Tangga | O28: +62 851-5520-1130 | P28: 317222110033 | Q28: mandaswari@gmail.com | R28: 73.33 | S28: 2025-11-20 15:38:02 | T28: 2025-11-20 15:44:25 | U28: 6.3833333 | V28: 0 | W28: Disetujui | X28: 20251204 12:44:49 | Y28: =IF(N28="",M28,N28) -> Mengurus Rumah Tangga | Z28: =VLOOKUP(H28,'[1]KELAS (REF) 1080'!$Q:$R,2,FALSE) -> #REF!
A29: Amar Ridhwan Pangestu | B29: Mitra (Pendataan dan Pengolahan) | C29: Diterima | D29: Mitra (Pendataan dan Pengolahan) | E29: Jalan Salak 6 No. 8 | F29: 32 | G29: 75 | H29: 060 | I29: 005 | J29: KLATEN, 11 Desember 2000 (26) | K29: Lk | L29: Tamat D4/S1 | M29: Pelajar / Mahasiswa | O29: +62 819-9918-7322 | P29: 317222110037 | Q29: Ridhwanamar18@gmail.com | R29: 80.00 | S29: 2025-11-20 13:00:43 | T29: 2025-11-20 13:25:53 | U29: 25.166667 | V29: 0 | W29: Disetujui | X29: 20251208 17:16:43 | Y29: =IF(N29="",M29,N29) -> Pelajar / Mahasiswa | Z29: =VLOOKUP(H29,'[1]KELAS (REF) 1080'!$Q:$R,2,FALSE) -> #REF!
A30: Ambar berlina | B30: Mitra (Pendataan dan Pengolahan) | C30: Diterima | D30: Mitra (Pendataan dan Pengolahan) | E30: Kp.siluman rt003 rw001 no.30 | F30: 32 | G30: 16 | H30: 081 | I30: 009 | J30: JAKARTA TIMUR, 24 Desember 1988 (38) | K30: Pr | L30: Tamat D4/S1 | M30: Mengurus Rumah Tangga | O30: +62 811-1682-811 | P30: 317222110004 | Q30: ambarberlina69@gmail.com | R30: 96.67 | S30: 2025-11-19 14:07:18 | T30: 2025-11-19 14:23:02 | U30: 15.733333 | V30: 0 | W30: Disetujui | X30: 20251204 12:58:42 | Y30: =IF(N30="",M30,N30) -> Mengurus Rumah Tangga | Z30: =VLOOKUP(H30,'[1]KELAS (REF) 1080'!$Q:$R,2,FALSE) -> #REF!
A31: Amelia Dita Purnama | B31: Mitra (Pendataan dan Pengolahan) | C31: Diterima | D31: Mitra (Pendataan dan Pengolahan) | E31: Jl. Cipinang Pulo Maja RT:007/011 No.21 | F31: 31 | G31: 72 | H31: 060 | I31: 005 | J31: , 19 Maret 2000 (26) | K31: Pr | L31: Tamat D4/S1 | M31: Pelajar / Mahasiswa | O31: +62 895-1685-1724 | P31: 317222110079 | Q31: ameliadtp1@gmail.com | R31: 100.00 | S31: 2025-11-25 12:43:55 | T31: 2025-11-25 13:01:37 | U31: 17.7 | V31: 0 | W31: Disetujui | X31: 20251205 09:20:43 | Y31: =IF(N31="",M31,N31) -> Pelajar / Mahasiswa | Z31: =VLOOKUP(H31,'[1]KELAS (REF) 1080'!$Q:$R,2,FALSE) -> #REF!
A32: Aminah | B32: Mitra (Pendataan dan Pengolahan) | C32: Diterima | D32: Mitra (Pendataan dan Pengolahan) | E32: Kp. Pegangsaan I RT.001 RW.003 no.44 | F32: 31 | G32: 72 | H32: 080 | I32: 007 | J32: JAKARTA UTARA, 03 September 1987 (39) | K32: Pr | L32: Tamat SMA/Sederajat | M32: Kader PKK / Karang Taruna / Kader Lainnya | O32: +62 858-8306-1812 | P32: 317222010006 | Q32: lemonlover76@gmail.com | R32: 80.00 | S32: 2025-11-21 16:55:53 | T32: 2025-11-21 17:26:59 | U32: 31.1 | V32: 0 | W32: Disetujui | X32: 20251205 18:44:40 | Y32: =IF(N32="",M32,N32) -> Kader PKK / Karang Taruna / Kader Lainnya | Z32: =VLOOKUP(H32,'[1]KELAS (REF) 1080'!$Q:$R,2,FALSE) -> #REF!
A33: Andhita Resha Kusuma | B33: Mitra (Pendataan dan Pengolahan) | C33: Diterima | D33: Mitra (Pendataan dan Pengolahan) | E33: Jl masjid Sabilillah gang remaja | F33: 31 | G33: 72 | H33: 040 | I33: 005 | J33: JAKARTA TIMUR, 03 Juli 1997 (29) | K33: Pr | L33: Tamat SMA/Sederajat | M33: Mengurus Rumah Tangga | O33: +62 895-2054-2418 | P33: 317222010444 | Q33: dhitaandhita1803@gmail.com | R33: 93.33 | S33: 2025-11-18 11:06:43 | T33: 2025-11-18 11:24:56 | U33: 18.216667 | V33: 0 | W33: Disetujui | X33: 20251205 17:03:20 | Y33: =IF(N33="",M33,N33) -> Mengurus Rumah Tangga | Z33: =VLOOKUP(H33,'[1]KELAS (REF) 1080'!$Q:$R,2,FALSE) -> #REF!
A34: Anggita fatmawanti | B34: Mitra (Pendataan dan Pengolahan) | C34: Diterima | D34: Mitra (Pendataan dan Pengolahan) | E34: Jl.kebon kelapa Gang.oyot 1 No.25 | F34: 31 | G34: 72 | H34: 100 | I34: 005 | J34: , 20 November 1985 (41) | K34: Pr | L34: Tamat SMA/Sederajat | M34: Mengurus Rumah Tangga | O34: 81380111995 | P34: 317222090589 | Q34: anggitafatmawati10@gmail.com | R34: 93.33 | S34: 2025-11-21 15:00:24 | T34: 2025-11-21 15:23:49 | U34: 23.416667 | V34: 0 | W34: Disetujui | X34: 20251204 13:02:28 | Y34: =IF(N34="",M34,N34) -> Mengurus Rumah Tangga | Z34: =VLOOKUP(H34,'[1]KELAS (REF) 1080'!$Q:$R,2,FALSE) -> #REF!
A35: Anggita Septiani | B35: Mitra (Pendataan dan Pengolahan) | C35: Diterima | D35: Mitra (Pendataan dan Pengolahan) | E35: Jl. H. Yahya dalam II No. 51E RT 14 RW 10 | F35: 31 | G35: 72 | H35: 060 | I35: 001 | J35: JAKARTA TIMUR, 17 September 2002 (24) | K35: Pr | L35: Tamat SMA/Sederajat | M35: Pelajar / Mahasiswa | O35: +62 812-1379-7684 | P35: 317222091450 | Q35: Septianianggita806@gmail.com | R35: 93.33 | S35: 2025-11-21 16:17:42 | T35: 2025-11-21 16:31:38 | U35: 13.933333 | V35: 0 | W35: Disetujui | X35: 20251204 14:17:42 | Y35: =IF(N35="",M35,N35) -> Pelajar / Mahasiswa | Z35: =VLOOKUP(H35,'[1]KELAS (REF) 1080'!$Q:$R,2,FALSE) -> #REF!
A36: Ani Muryani | B36: Mitra (Pendataan dan Pengolahan) | C36: Diterima | D36: Mitra (Pendataan dan Pengolahan) | E36: jl. inspeksi kali Sunter No. 18 RT. 006/01 | F36: 31 | G36: 72 | H36: 090 | I36: 007 | J36: JAKARTA TIMUR, 20 Mei 1982 (44) | K36: Pr | L36: Tamat SMA/Sederajat | M36: Mengurus Rumah Tangga | O36: +62 888-8525-187 | P36: 317222040007 | Q36: animuryani82@gmail.com | R36: 93.33 | S36: 2025-11-18 11:02:37 | T36: 2025-11-18 11:36:13 | U36: 33.6 | V36: 0 | W36: Disetujui | X36: 20251204 16:35:04 | Y36: =IF(N36="",M36,N36) -> Mengurus Rumah Tangga | Z36: =VLOOKUP(H36,'[1]KELAS (REF) 1080'!$Q:$R,2,FALSE) -> #REF!
A37: Ani Nusantari | B37: Mitra (Pendataan dan Pengolahan) | C37: Diterima | D37: Mitra (Pendataan dan Pengolahan) | E37: Jl. Cipinang Asem RT 008 RW 012 | F37: 31 | G37: 72 | H37: 040 | I37: 003 | J37: SEMARANG, 12 November 1979 (47) | K37: Pr | L37: Tamat SMA/Sederajat | M37: Mengurus Rumah Tangga | O37: +62 878-8968-0432 | P37: 317223070003 | Q37: atari5060@gmail.com | R37: 100.00 | S37: 2025-11-21 13:30:30 | T37: 2025-11-21 14:01:00 | U37: 30.5 | V37: 0 | W37: Disetujui | X37: 20251205 16:26:18 | Y37: =IF(N37="",M37,N37) -> Mengurus Rumah Tangga | Z37: =VLOOKUP(H37,'[1]KELAS (REF) 1080'!$Q:$R,2,FALSE) -> #REF!
A38: Anicah | B38: Mitra Pendataan | C38: Diterima | D38: Mitra Pendataan | E38: Jln. Kebon Sereh Barat no.6 rt 008 rw 10 | F38: 31 | G38: 72 | H38: 100 | I38: 003 | J38: SUMEDANG, 04 Februari 1967 (59) | K38: Pr | L38: Tamat SMA/Sederajat | M38: Mengurus Rumah Tangga | O38: +62 858-1165-3188 | P38: 317223050005 | Q38: anicahendar@gmail.com | R38: 80.00 | S38: 2025-11-19 11:04:01 | T38: 2025-11-19 11:50:21 | U38: 46.333333 | V38: 0 | W38: Disetujui | X38: 20251204 09:59:29 | Y38: =IF(N38="",M38,N38) -> Mengurus Rumah Tangga | Z38: =VLOOKUP(H38,'[1]KELAS (REF) 1080'!$Q:$R,2,FALSE) -> #REF!
A39: Anita Damayanti | B39: Mitra (Pendataan dan Pengolahan) | C39: Diterima | D39: Mitra (Pendataan dan Pengolahan) | E39: Jl tipar kp raden rt 007/07 | F39: 31 | G39: 72 | H39: 010 | I39: 001 | J39: JAKARTA TIMUR, 09 April 1979 (47) | K39: Pr | L39: Tamat SMA/Sederajat | M39: Kader PKK / Karang Taruna / Kader Lainnya | O39: +62 812-1363-107 | P39: 317222010460 | Q39: damayantianita0@gmail.com | R39: 93.33 | S39: 2025-11-21 15:02:10 | T39: 2025-11-21 15:34:33 | U39: 32.383333 | V39: 0 | W39: Disetujui | X39: 20251204 12:32:48 | Y39: =IF(N39="",M39,N39) -> Kader PKK / Karang Taruna / Kader Lainnya | Z39: =VLOOKUP(H39,'[1]KELAS (REF) 1080'!$Q:$R,2,FALSE) -> #REF!
... A41: Annisa Luna Felita | B41: Mitra (Pendataan dan Pengolahan) | C41: Diterima | D41: Mitra (Pendataan dan Pengolahan) | E41: Jalan Kerja Bakti Nomor 28 Rt 001/ Rw 02 | F41: 31 | G41: 72 | H41: 040 | I41: 002 | J41: , 19 April 2007 (19) | K41: Pr | L41: Tamat SMA/Sederajat | M41: Pelajar / Mahasiswa | O41: +62 858-9362-9852 | P41: 317225050081 | Q41: fela2516@gmail.com | R41: 96.67 | S41: 2025-11-20 15:02:36 | T41: 2025-11-20 16:01:21 | U41: 58.75 | V41: 0 | W41: Disetujui | X41: 20251205 17:38:40 | Y41: =IF(N41="",M41,N41) -> Pelajar / Mahasiswa | Z41: =VLOOKUP(H41,'[1]KELAS (REF) 1080'!$Q:$R,2,FALSE) -> #REF!
...

Sheet KELAS (REFERENSI)
A1: No | B1: Gelombang | C1: TC | D1: Kelas | E1: Gel-Kelas | F1: Kapasitas | G1: Panitia | H1: Inda | I1: PJ | J1: TC | K1: Jadwal Mulai MOOC | L1: Jadwal Selesai KELAS | M1: Hari | N1: Tanggal | O1: Bulan | P1: Tahun | Q1: Tanggal Kontrak | S1: TGR | V1: Kode Kec | W1: Nama Kec | Y1: HOTEL | AE1: HOTEL BWP 1 | AK1: HOTEL BWP 2 | AQ1: HOTEL BWP 3 | AW1: HOTEL BWP 4 | BC1: HOTEL HARPER 1 | BI1: HOTEL HARPER 2 | BO1: HOTEL HARPER 3 | BU1: HOTEL PARK 1 | CA1: HOTEL PARK 2 | CG1: HOTEL PARK 3 | CM1: TOTAL | CQ1: PER GELOMBANG
A2: 1 | B2: 1 | C2: BWP | D2: A | E2: =B2&D2 -> 1A | F2: 28 | G2: 2 | H2: 1 | I2: 1 | J2: =C2 -> BWP | K2: 29 Mei 2026 | L2: 03 Juni 2026 | M2: Selasa | N2: Dua Puluh Enam | O2: Mei | P2: Dua Ribu Dua Puluh Enam | Q2: 26 Mei 2026 | S2: Fullday | T2: =AA8*3 -> 1290000 | V2: 010 | W2: Pasar Rebo | Y2: Item | Z2: Vol | AA2: Harga Sat | AB2: Hari | AC2: Total | AE2: Item | AF2: Vol | AG2: Harga Sat | AH2: Hari | AI2: Total | AK2: Item | AL2: Vol | AM2: Harga Sat | AN2: Hari | AO2: Total | AQ2: Item | AR2: Vol | AS2: Harga Sat | AT2: Hari | AU2: Total | AW2: Item | AX2: Vol | AY2: Harga Sat | AZ2: Hari | BA2: Total | BC2: Item | BD2: Vol | BE2: Harga Sat | BF2: Hari | BG2: Total | BI2: Item | BJ2: Vol | BK2: Harga Sat | BL2: Hari | BM2: Total | BO2: Item | BP2: Vol | BQ2: Harga Sat | BR2: Hari | BS2: Total | BU2: Item | BV2: Vol | BW2: Harga Sat | BX2: Hari | BY2: Total | CA2: Item | CB2: Vol | CC2: Harga Sat | CD2: Hari | CE2: Total | CG2: Item | CH2: Vol | CI2: Harga Sat | CJ2: Hari | CK2: Total | CM2: KONTROL | CN2: TOTAL | CO2: SELISIH | CQ2: G1 | CR2: G2 | CS2: G3 | CT2: G4 | CU2: TOTAL
A3: 2 | B3: 1 | C3: BWP | D3: B | E3: =B3&D3 -> 1B | F3: 28 | G3: 2 | H3: 1 | J3: =C3 -> BWP | K3: =IF(B3=B2,K2,"") -> 29 Mei 2026 | L3: =IF(B3=B2,L2,"") -> 03 Juni 2026 | M3: =IF(B3=B2,M2,"") -> Selasa | N3: =IF(B3=B2,N2,"") -> Dua Puluh Enam | O3: =IF(B3=B2,O2,"") -> Mei | P3: =IF(B3=B2,P2,"") -> Dua Ribu Dua Puluh Enam | Q3: =IF(B3=B2,Q2,"") -> 26 Mei 2026 | S3: Konsumsi | T3: =105000*3 -> 315000 | V3: 020 | W3: Ciracas | Y3: Petugas | Z3: =1844-25-7-Z16 -> 1312 | AE3: Petugas | AF3: =28*5+25 -> 165 | AK3: Petugas | AL3: =28*5+25 -> 165 | AQ3: Petugas | AR3: =28*5+25 -> 165 | AW3: Petugas | AX3: =28*3 -> 84 | BC3: Petugas | BD3: =28*4 -> 112 | BI3: Petugas | BJ3: =27*4 -> 108 | BO3: Petugas | BP3: =27*5 -> 135 | BU3: Petugas | BV3: =27*5 -> 135 | CA3: Petugas | CB3: =27*5 -> 135 | CG3: Petugas | CH3: =Z3-AF3-AR3-AL3-BD3-BJ3-BP3-BV3-CB3-AX3 -> 108 | CM3: =Z3 -> 1312 | CN3: =AF3+AR3+AL3+BD3+BJ3+BP3+BV3+CB3+CH3+AX3 -> 1312 | CO3: =CN3-CM3 -> 0 | CQ3: =AF3+BD3+BV3 -> 412 | CR3: =AL3+BJ3+CB3 -> 408 | CS3: =AR3+BP3+CH3 -> 408 | CT3: =AX3 -> 84 | CU3: =SUM(CQ3:CT3) -> 1312
A4: 3 | B4: 1 | C4: BWP | D4: C | E4: =B4&D4 -> 1C | F4: 28 | G4: 2 | H4: 1 | J4: =C4 -> BWP | K4: =IF(B4=B3,K3,"") -> 29 Mei 2026 | L4: =IF(B4=B3,L3,"") -> 03 Juni 2026 | M4: =IF(B4=B3,M3,"") -> Selasa | N4: =IF(B4=B3,N3,"") -> Dua Puluh Enam | O4: =IF(B4=B3,O3,"") -> Mei | P4: =IF(B4=B3,P3,"") -> Dua Ribu Dua Puluh Enam | Q4: =IF(B4=B3,Q3,"") -> 26 Mei 2026 | S4: Transport | T4: =150000*3 -> 450000 | V4: 030 | W4: Cipayung | Y4: Kelas | Z4: 48 | AD4: =Z3/Z4 -> 27.333333 | AE4: Kelas | AF4: 6 | AJ4: =AF3/AF4 -> 27.5 | AK4: Kelas | AL4: 6 | AP4: =AL3/AL4 -> 27.5 | AQ4: Kelas | AR4: 6 | AV4: =AR3/AR4 -> 27.5 | AW4: Kelas | AX4: 3 | BB4: =AX3/AX4 -> 28 | BC4: Kelas | BD4: 4 | BH4: =BD3/BD4 -> 28 | BI4: Kelas | BJ4: 4 | BN4: =BJ3/BJ4 -> 27 | BO4: Kelas | BP4: 5 | BT4: =BP3/BP4 -> 27 | BU4: Kelas | BV4: 5 | BZ4: =BV3/BV4 -> 27 | CA4: Kelas | CB4: 5 | CF4: =CB3/CB4 -> 27 | CG4: Kelas | CH4: =Z4-AF4-AR4-AL4-BD4-BJ4-BP4-BV4-CB4-AX4 -> 4 | CL4: =CH3/CH4 -> 27 | CM4: =Z4 -> 48 | CN4: =AF4+AR4+AL4+BD4+BJ4+BP4+BV4+CB4+CH4+AX4 -> 48 | CO4: =CN4-CM4 -> 0 | CP4: =CN3/CN4 -> 27.333333 | CQ4: =AF4+BD4+BV4 -> 15 | CR4: =AL4+BJ4+CB4 -> 15 | CS4: =AR4+BP4+CH4 -> 15 | CT4: =AX4 -> 3 | CU4: =SUM(CQ4:CT4) -> 48 | CV4: =CU3/CU4 -> 27.333333
A5: 4 | B5: 1 | C5: BWP | D5: D | E5: =B5&D5 -> 1D | F5: 28 | G5: 2 | H5: 1 | J5: =C5 -> BWP | K5: =IF(B5=B4,K4,"") -> 29 Mei 2026 | L5: =IF(B5=B4,L4,"") -> 03 Juni 2026 | M5: =IF(B5=B4,M4,"") -> Selasa | N5: =IF(B5=B4,N4,"") -> Dua Puluh Enam | O5: =IF(B5=B4,O4,"") -> Mei | P5: =IF(B5=B4,P4,"") -> Dua Ribu Dua Puluh Enam | Q5: =IF(B5=B4,Q4,"") -> 26 Mei 2026 | V5: 040 | W5: Makasar | Y5: Inda | Z5: =Z4 -> 48 | AE5: Inda | AF5: =AF4 -> 6 | AK5: Inda | AL5: =AL4 -> 6 | AQ5: Inda | AR5: =AR4 -> 6 | AW5: Inda | AX5: =AX4 -> 3 | BC5: Inda | BD5: =BD4 -> 4 | BI5: Inda | BJ5: =BJ4 -> 4 | BO5: Inda | BP5: =BP4 -> 5 | BU5: Inda | BV5: =BV4 -> 5 | CA5: Inda | CB5: =CB4 -> 5 | CG5: Inda | CH5: =Z5-AF5-AR5-AL5-BD5-BJ5-BP5-BV5-CB5-AX5 -> 4 | CM5: =Z5 -> 48 | CN5: =AF5+AR5+AL5+BD5+BJ5+BP5+BV5+CB5+CH5+AX5 -> 48 | CO5: =CN5-CM5 -> 0 | CQ5: =AF5+BD5+BV5 -> 15 | CR5: =AL5+BJ5+CB5 -> 15 | CS5: =AR5+BP5+CH5 -> 15 | CT5: =AX5 -> 3 | CU5: =SUM(CQ5:CT5) -> 48
A6: 5 | B6: 1 | C6: BWP | D6: E | E6: =B6&D6 -> 1E | F6: 28 | G6: 2 | H6: 1 | J6: =C6 -> BWP | K6: =IF(B6=B5,K5,"") -> 29 Mei 2026 | L6: =IF(B6=B5,L5,"") -> 03 Juni 2026 | M6: =IF(B6=B5,M5,"") -> Selasa | N6: =IF(B6=B5,N5,"") -> Dua Puluh Enam | O6: =IF(B6=B5,O5,"") -> Mei | P6: =IF(B6=B5,P5,"") -> Dua Ribu Dua Puluh Enam | Q6: =IF(B6=B5,Q5,"") -> 26 Mei 2026 | S6: TGR HOTEL | T6: =T2+T4 -> 1740000 | V6: 050 | W6: Kramat jati | Y6: Panitia | Z6: =Z4*2 -> 96 | AE6: Panitia | AF6: =AF4*2 -> 12 | AK6: Panitia | AL6: =AL4*2 -> 12 | AQ6: Panitia | AR6: =AR4*2 -> 12 | AW6: Panitia | AX6: =AX4*2 -> 6 | BC6: Panitia | BD6: =BD4*2 -> 8 | BI6: Panitia | BJ6: =BJ4*2 -> 8 | BO6: Panitia | BP6: =BP4*2 -> 10 | BU6: Panitia | BV6: =BV4*2 -> 10 | CA6: Panitia | CB6: =CB4*2 -> 10 | CG6: Panitia | CH6: =Z6-AF6-AR6-AL6-BD6-BJ6-BP6-BV6-CB6-AX6 -> 8 | CM6: =Z6 -> 96 | CN6: =AF6+AR6+AL6+BD6+BJ6+BP6+BV6+CB6+CH6+AX6 -> 96 | CO6: =CN6-CM6 -> 0 | CQ6: =AF6+BD6+BV6 -> 30 | CR6: =AL6+BJ6+CB6 -> 30 | CS6: =AR6+BP6+CH6 -> 30 | CT6: =AX6 -> 6 | CU6: =SUM(CQ6:CT6) -> 96
A7: 6 | B7: 1 | C7: BWP | D7: F | E7: =B7&D7 -> 1F | F7: 25 | G7: 2 | H7: 1 | J7: =C7 -> BWP | K7: =IF(B7=B6,K6,"") -> 29 Mei 2026 | L7: =IF(B7=B6,L6,"") -> 03 Juni 2026 | M7: =IF(B7=B6,M6,"") -> Selasa | N7: =IF(B7=B6,N6,"") -> Dua Puluh Enam | O7: =IF(B7=B6,O6,"") -> Mei | P7: =IF(B7=B6,P6,"") -> Dua Ribu Dua Puluh Enam | Q7: =IF(B7=B6,Q6,"") -> 26 Mei 2026 | S7: TGR STIS | T7: =T3 -> 315000 | V7: 060 | W7: Jatinegara | Y7: PJ | Z7: 3 | AE7: PJ | AF7: 1 | AK7: PJ | AL7: 1 | AQ7: PJ | AR7: 1 | AW7: PJ | AX7: 0 | BC7: PJ | BD7: 0 | BI7: PJ | BJ7: 0 | BO7: PJ | BP7: 0 | BU7: PJ | BV7: 0 | CA7: PJ | CB7: 0 | CG7: PJ | CH7: =Z7-AF7-AR7-AL7-BD7-BJ7-BP7-BV7-CB7-AX7 -> 0 | CM7: =Z7 -> 3 | CN7: =AF7+AR7+AL7+BD7+BJ7+BP7+BV7+CB7+CH7+AX7 -> 3 | CO7: =CN7-CM7 -> 0 | CQ7: =AF7+BD7+BV7 -> 1 | CR7: =AL7+BJ7+CB7 -> 1 | CS7: =AR7+BP7+CH7 -> 1 | CT7: =AX7 -> 0 | CU7: =SUM(CQ7:CT7) -> 3 | CX7: =1459+21 -> 1480
A8: 7 | B8: 1 | C8: HARPER | D8: G | E8: =B8&D8 -> 1G | F8: 28 | G8: 2 | H8: 1 | J8: =C8 -> HARPER | K8: =IF(B8=B7,K7,"") -> 29 Mei 2026 | L8: =IF(B8=B7,L7,"") -> 03 Juni 2026 | M8: =IF(B8=B7,M7,"") -> Selasa | N8: =IF(B8=B7,N7,"") -> Dua Puluh Enam | O8: =IF(B8=B7,O7,"") -> Mei | P8: =IF(B8=B7,P7,"") -> Dua Ribu Dua Puluh Enam | Q8: =IF(B8=B7,Q7,"") -> 26 Mei 2026 | V8: 070 | W8: Duren Sawit | Y8: Total Akomodasi | Z8: =Z3+Z5+Z6+Z7 -> 1459 | AA8: 430000 | AB8: 3 | AC8: =Z8*AA8*AB8 -> 1882110000 | AE8: Total Akomodasi | AF8: =AF3+AF5+AF6+AF7 -> 184 | AG8: 430000 | AH8: 3 | AI8: =AF8*AG8*AH8 -> 237360000 | AK8: Total Akomodasi | AL8: =AL3+AL5+AL6+AL7 -> 184 | AM8: 430000 | AN8: 3 | AO8: =AL8*AM8*AN8 -> 237360000 | AQ8: Total Akomodasi | AR8: =AR3+AR5+AR6+AR7 -> 184 | AS8: 430000 | AT8: 3 | AU8: =AR8*AS8*AT8 -> 237360000 | AW8: Total Akomodasi | AX8: =AX3+AX5+AX6+AX7 -> 93 | AY8: 430000 | AZ8: 3 | BA8: =AX8*AY8*AZ8 -> 119970000 | BC8: Total Akomodasi | BD8: =BD3+BD5+BD6+BD7 -> 124 | BE8: 430000 | BF8: 3 | BG8: =BD8*BE8*BF8 -> 159960000 | BI8: Total Akomodasi | BJ8: =BJ3+BJ5+BJ6+BJ7 -> 120 | BK8: 430000 | BL8: 3 | BM8: =BJ8*BK8*BL8 -> 154800000 | BO8: Total Akomodasi | BP8: =BP3+BP5+BP6+BP7 -> 150 | BQ8: 430000 | BR8: 3 | BS8: =BP8*BQ8*BR8 -> 193500000 | BU8: Total Akomodasi | BV8: =BV3+BV5+BV6+BV7 -> 150 | BW8: 400000 | BX8: 3 | BY8: =BV8*BW8*BX8 -> 180000000 | CA8: Total Akomodasi | CB8: =CB3+CB5+CB6+CB7 -> 150 | CC8: 400000 | CD8: 3 | CE8: =CB8*CC8*CD8 -> 180000000 | CG8: Total Akomodasi | CH8: =Z8-AF8-AR8-AL8-BD8-BJ8-BP8-BV8-CB8-AX8 -> 120 | CI8: 400000 | CJ8: 3 | CK8: =CH8*CI8*CJ8 -> 144000000 | CM8: =Z8 -> 1459 | CN8: =AF8+AR8+AL8+BD8+BJ8+BP8+BV8+CB8+CH8+AX8 -> 1459 | CO8: =CN8-CM8 -> 0 | CQ8: =AF8+BD8+BV8 -> 458 | CR8: =AL8+BJ8+CB8 -> 454 | CS8: =AR8+BP8+CH8 -> 454 | CT8: =AX8 -> 93 | CU8: =SUM(CQ8:CT8) -> 1459 | CX8: =CX7*3 -> 4440 | CY8: =30000*CX8 -> 133200000
A9: 8 | B9: 1 | C9: HARPER | D9: H | E9: =B9&D9 -> 1H | F9: 28 | G9: 2 | H9: 1 | J9: =C9 -> HARPER | K9: =IF(B9=B8,K8,"") -> 29 Mei 2026 | L9: =IF(B9=B8,L8,"") -> 03 Juni 2026 | M9: =IF(B9=B8,M8,"") -> Selasa | N9: =IF(B9=B8,N8,"") -> Dua Puluh Enam | O9: =IF(B9=B8,O8,"") -> Mei | P9: =IF(B9=B8,P8,"") -> Dua Ribu Dua Puluh Enam | Q9: =IF(B9=B8,Q8,"") -> 26 Mei 2026 | V9: 080 | W9: Cakung | Y9: Transport Peserta | Z9: =Z3+Z5+Z6 -> 1456 | AA9: 170000 | AB9: 3 | AC9: =Z9*AA9*AB9 -> 742560000 | AE9: Transport Peserta | AF9: =AF3+AF5+AF6 -> 183 | AG9: 170000 | AH9: 3 | AI9: =AF9*AG9*AH9 -> 93330000 | AK9: Transport Peserta | AL9: =AL3+AL5+AL6 -> 183 | AM9: 170000 | AN9: 3 | AO9: =AL9*AM9*AN9 -> 93330000 | AQ9: Transport Peserta | AR9: =AR3+AR5+AR6 -> 183 | AS9: 170000 | AT9: 3 | AU9: =AR9*AS9*AT9 -> 93330000 | AW9: Transport Peserta | AX9: =AX3+AX5+AX6 -> 93 | AY9: 170000 | AZ9: 3 | BA9: =AX9*AY9*AZ9 -> 47430000 | BC9: Transport Peserta | BD9: =BD3+BD5+BD6 -> 124 | BE9: 170000 | BF9: 3 | BG9: =BD9*BE9*BF9 -> 63240000 | BI9: Transport Peserta | BJ9: =BJ3+BJ5+BJ6 -> 120 | BK9: 170000 | BL9: 3 | BM9: =BJ9*BK9*BL9 -> 61200000 | BO9: Transport Peserta | BP9: =BP3+BP5+BP6 -> 150 | BQ9: 170000 | BR9: 3 | BS9: =BP9*BQ9*BR9 -> 76500000 | BU9: Transport Peserta | BV9: =BV3+BV5+BV6 -> 150 | BW9: 170000 | BX9: 3 | BY9: =BV9*BW9*BX9 -> 76500000 | CA9: Transport Peserta | CB9: =CB3+CB5+CB6 -> 150 | CC9: 170000 | CD9: 3 | CE9: =CB9*CC9*CD9 -> 76500000 | CG9: Transport Peserta | CH9: =Z9-AF9-AR9-AL9-BD9-BJ9-BP9-BV9-CB9-AX9 -> 120 | CI9: 170000 | CJ9: 3 | CK9: =CH9*CI9*CJ9 -> 61200000 | CM9: =Z9 -> 1456 | CN9: =AF9+AR9+AL9+BD9+BJ9+BP9+BV9+CB9+CH9+AX9 -> 1456 | CO9: =CN9-CM9 -> 0 | CQ9: =AF9+BD9+BV9 -> 457 | CR9: =AL9+BJ9+CB9 -> 453 | CS9: =AR9+BP9+CH9 -> 453 | CT9: =AX9 -> 93 | CU9: =SUM(CQ9:CT9) -> 1456
A10: 9 | B10: 1 | C10: HARPER | D10: I | E10: =B10&D10 -> 1I | F10: 28 | G10: 2 | H10: 1 | J10: =C10 -> HARPER | K10: =IF(B10=B9,K9,"") -> 29 Mei 2026 | L10: =IF(B10=B9,L9,"") -> 03 Juni 2026 | M10: =IF(B10=B9,M9,"") -> Selasa | N10: =IF(B10=B9,N9,"") -> Dua Puluh Enam | O10: =IF(B10=B9,O9,"") -> Mei | P10: =IF(B10=B9,P9,"") -> Dua Ribu Dua Puluh Enam | Q10: =IF(B10=B9,Q9,"") -> 26 Mei 2026 | V10: 081 | W10: Luar Jakarta Timur | Y10: Perjadin PJ | Z10: 3 | AA10: 0 | AB10: 3 | AC10: =Z10*AA10*AB10 -> 0 | AE10: Perjadin PJ | AF10: 1 | AG10: 0 | AH10: 3 | AI10: =AF10*AG10*AH10 -> 0 | AK10: Perjadin PJ | AL10: 1 | AM10: 0 | AN10: 3 | AO10: =AL10*AM10*AN10 -> 0 | AQ10: Perjadin PJ | AR10: 1 | AS10: 0 | AT10: 3 | AU10: =AR10*AS10*AT10 -> 0 | AW10: Perjadin PJ | AX10: 0 | AY10: 0 | AZ10: 3 | BA10: =AX10*AY10*AZ10 -> 0 | BC10: Perjadin PJ | BD10: 0 | BE10: 0 | BF10: 0 | BG10: =BD10*BE10*BF10 -> 0 | BI10: Perjadin PJ | BJ10: 0 | BK10: 0 | BL10: 0 | BM10: =BJ10*BK10*BL10 -> 0 | BO10: Perjadin PJ | BP10: 0 | BQ10: 0 | BR10: 0 | BS10: =BP10*BQ10*BR10 -> 0 | BU10: Perjadin PJ | BV10: 0 | BW10: 0 | BX10: 0 | BY10: =BV10*BW10*BX10 -> 0 | CA10: Perjadin PJ | CB10: 0 | CC10: 0 | CD10: 0 | CE10: =CB10*CC10*CD10 -> 0 | CG10: Perjadin PJ | CH10: =Z10-AF10-AR10-AL10-BD10-BJ10-BP10-BV10-CB10-AX10 -> 0 | CI10: 0 | CJ10: 0 | CK10: =CH10*CI10*CJ10 -> 0 | CM10: =Z10 -> 3 | CN10: =AF10+AR10+AL10+BD10+BJ10+BP10+BV10+CB10+CH10+AX10 -> 3 | CO10: =CN10-CM10 -> 0 | CQ10: =AF10+BD10+BV10 -> 1 | CR10: =AL10+BJ10+CB10 -> 1 | CS10: =AR10+BP10+CH10 -> 1 | CT10: =AX10 -> 0 | CU10: =SUM(CQ10:CT10) -> 3
A11: 10 | B11: 1 | C11: HARPER | D11: J | E11: =B11&D11 -> 1J | F11: 28 | G11: 2 | H11: 1 | J11: =C11 -> HARPER | K11: =IF(B11=B10,K10,"") -> 29 Mei 2026 | L11: =IF(B11=B10,L10,"") -> 03 Juni 2026 | M11: =IF(B11=B10,M10,"") -> Selasa | N11: =IF(B11=B10,N10,"") -> Dua Puluh Enam | O11: =IF(B11=B10,O10,"") -> Mei | P11: =IF(B11=B10,P10,"") -> Dua Ribu Dua Puluh Enam | Q11: =IF(B11=B10,Q10,"") -> 26 Mei 2026 | V11: 090 | W11: Pulo Gadung | Y11: Transport Role Playing | Z11: =Z4*3 -> 144 | AA11: 150000 | AB11: 1 | AC11: =Z11*AA11*AB11 -> 21600000 | AE11: Transport Role Playing | AF11: =AF4*3 -> 18 | AG11: 170000 | AH11: 1 | AI11: =AF11*AG11*AH11 -> 3060000 | AK11: Transport Role Playing | AL11: =AL4*3 -> 18 | AM11: 170000 | AN11: 1 | AO11: =AL11*AM11*AN11 -> 3060000 | AQ11: Transport Role Playing | AR11: =AR4*3 -> 18 | AS11: 170000 | AT11: 1 | AU11: =AR11*AS11*AT11 -> 3060000 | AW11: Transport Role Playing | AX11: =AX4*3 -> 9 | AY11: 170000 | AZ11: 1 | BA11: =AX11*AY11*AZ11 -> 1530000 | BC11: Transport Role Playing | BD11: =BD4*3 -> 12 | BE11: 170000 | BF11: 1 | BG11: =BD11*BE11*BF11 -> 2040000 | BI11: Transport Role Playing | BJ11: =BJ4*3 -> 12 | BK11: 170000 | BL11: 1 | BM11: =BJ11*BK11*BL11 -> 2040000 | BO11: Transport Role Playing | BP11: =BP4*3 -> 15 | BQ11: 170000 | BR11: 1 | BS11: =BP11*BQ11*BR11 -> 2550000 | BU11: Transport Role Playing | BV11: =BV4*3 -> 15 | BW11: 170000 | BX11: 1 | BY11: =BV11*BW11*BX11 -> 2550000 | CA11: Transport Role Playing | CB11: =CB4*3 -> 15 | CC11: 170000 | CD11: 1 | CE11: =CB11*CC11*CD11 -> 2550000 | CG11: Transport Role Playing | CH11: =Z11-AF11-AR11-AL11-BD11-BJ11-BP11-BV11-CB11-AX11 -> 12 | CI11: 170000 | CJ11: 1 | CK11: =CH11*CI11*CJ11 -> 2040000 | CM11: =Z11 -> 144 | CN11: =AF11+AR11+AL11+BD11+BJ11+BP11+BV11+CB11+CH11+AX11 -> 144 | CO11: =CN11-CM11 -> 0 | CQ11: =AF11+BD11+BV11 -> 45 | CR11: =AL11+BJ11+CB11 -> 45 | CS11: =AR11+BP11+CH11 -> 45 | CT11: =AX11 -> 9 | CU11: =SUM(CQ11:CT11) -> 144
A12: 11 | B12: 1 | C12: PARK | D12: K | E12: =B12&D12 -> 1K | F12: 27 | G12: 2 | H12: 1 | J12: =C12 -> PARK | K12: =IF(B12=B11,K11,"") -> 29 Mei 2026 | L12: =IF(B12=B11,L11,"") -> 03 Juni 2026 | M12: =IF(B12=B11,M11,"") -> Selasa | N12: =IF(B12=B11,N11,"") -> Dua Puluh Enam | O12: =IF(B12=B11,O11,"") -> Mei | P12: =IF(B12=B11,P11,"") -> Dua Ribu Dua Puluh Enam | Q12: =IF(B12=B11,Q11,"") -> 26 Mei 2026 | V12: 100 | W12: Matraman | Y12: TOTAL HOTEL | AC12: =SUM(AC8:AC11) -> 2646270000 | AE12: TOTAL BWP 1 | AI12: =SUM(AI8:AI11) -> 333750000 | AK12: TOTAL BWP 2 | AO12: =SUM(AO8:AO11) -> 333750000 | AQ12: TOTAL BWP 3 | AU12: =SUM(AU8:AU11) -> 333750000 | AW12: TOTAL BWP 4 | BA12: =SUM(BA8:BA11) -> 168930000 | BC12: TOTAL HARPER 1 | BG12: =SUM(BG8:BG11) -> 225240000 | BI12: TOTAL HARPER 2 | BM12: =SUM(BM8:BM11) -> 218040000 | BO12: TOTAL HARPER 3 | BS12: =SUM(BS8:BS11) -> 272550000 | BU12: TOTAL PARK 1 | BY12: =SUM(BY8:BY11) -> 259050000 | CA12: TOTAL PARK 2 | CE12: =SUM(CE8:CE11) -> 259050000 | CG12: TOTAL PARK 3 | CK12: =SUM(CK8:CK11) -> 207240000 | CM12: =AC12 -> 2646270000 | CN12: =AI12+AO12+AU12+BG12+BM12+BS12+BY12+CE12+CK12+BA12 -> 2611350000 | CO12: =CN12-CM12 -> -34920000 | CQ12: =AI12+BG12+BY12 -> 818040000 | CR12: =AO12+BM12+CE12 -> 810840000 | CS12: =AU12+BS12+CK12 -> 813540000 | CT12: =BA12 -> 168930000 | CU12: =SUM(CQ12:CT12) -> 2611350000
A13: 12 | B13: 1 | C13: PARK | D13: L | E13: =B13&D13 -> 1L | F13: 27 | G13: 2 | H13: 1 | J13: =C13 -> PARK | K13: =IF(B13=B12,K12,"") -> 29 Mei 2026 | L13: =IF(B13=B12,L12,"") -> 03 Juni 2026 | M13: =IF(B13=B12,M12,"") -> Selasa | N13: =IF(B13=B12,N12,"") -> Dua Puluh Enam | O13: =IF(B13=B12,O12,"") -> Mei | P13: =IF(B13=B12,P12,"") -> Dua Ribu Dua Puluh Enam | Q13: =IF(B13=B12,Q12,"") -> 26 Mei 2026 | CS13: SELISIH | CU13: =CU12-CM12 -> -34920000
A14: 13 | B14: 1 | C14: PARK | D14: M | E14: =B14&D14 -> 1M | F14: 27 | G14: 2 | H14: 1 | J14: =C14 -> PARK | K14: =IF(B14=B13,K13,"") -> 29 Mei 2026 | L14: =IF(B14=B13,L13,"") -> 03 Juni 2026 | M14: =IF(B14=B13,M13,"") -> Selasa | N14: =IF(B14=B13,N13,"") -> Dua Puluh Enam | O14: =IF(B14=B13,O13,"") -> Mei | P14: =IF(B14=B13,P13,"") -> Dua Ribu Dua Puluh Enam | Q14: =IF(B14=B13,Q13,"") -> 26 Mei 2026 | Y14: STIS | AE14: STIS 1 | AK14: STIS 2 | AQ14: TOTAL | CM14: HOTEL
A15: 14 | B15: 1 | C15: PARK | D15: N | E15: =B15&D15 -> 1N | F15: 27 | G15: 2 | H15: 1 | J15: =C15 -> PARK | K15: =IF(B15=B14,K14,"") -> 29 Mei 2026 | L15: =IF(B15=B14,L14,"") -> 03 Juni 2026 | M15: =IF(B15=B14,M14,"") -> Selasa | N15: =IF(B15=B14,N14,"") -> Dua Puluh Enam | O15: =IF(B15=B14,O14,"") -> Mei | P15: =IF(B15=B14,P14,"") -> Dua Ribu Dua Puluh Enam | Q15: =IF(B15=B14,Q14,"") -> 26 Mei 2026 | Y15: Item | Z15: Vol | AA15: Harga Sat | AB15: Hari | AC15: Total | AE15: Item | AF15: Vol | AG15: Harga Sat | AH15: Hari | AI15: Total | AK15: Item | AL15: Vol | AM15: Harga Sat | AN15: Hari | AO15: Total | AQ15: KONTROL | AR15: TOTAL | AS15: SELISIH | CM15: INDA | CN15: =CN4*25*123000 -> 147600000 | CO15: INDA | CP15: =CN15+CN21 -> 206025000 | CQ15: =CP15/(123000*25) -> 67
A16: 15 | B16: 1 | C16: PARK | D16: O | E16: =B16&D16 -> 1O | F16: 27 | G16: 2 | H16: 1 | J16: =C16 -> PARK | K16: =IF(B16=B15,K15,"") -> 29 Mei 2026 | L16: =IF(B16=B15,L15,"") -> 03 Juni 2026 | M16: =IF(B16=B15,M15,"") -> Selasa | N16: =IF(B16=B15,N15,"") -> Dua Puluh Enam | O16: =IF(B16=B15,O15,"") -> Mei | P16: =IF(B16=B15,P15,"") -> Dua Ribu Dua Puluh Enam | Q16: =IF(B16=B15,Q15,"") -> 26 Mei 2026 | Y16: Petugas | Z16: 500 | AE16: Petugas | AF16: 500 | AK16: Petugas | AL16: =Z16-AF16 -> 0 | AQ16: =Z16 -> 500 | AR16: =AF16+AL16 -> 500 | AS16: =AR16-AQ16 -> 0 | CM16: PM | CN16: =AI8+AO8+AU8+BG8+BM8+BS8+BY8+CE8+CK8+BA8 -> 1844310000 | CO16: PM | CP16: =CN16 -> 1844310000 | CQ16: =CP16/(455000) -> 4053.4286 | CR16: =CQ16+100 -> 4153.4286 | CS16: =455-430 -> 25 | CU16: =1400*CS16*1000 -> 35000000 | CV16: =1806000000-CP16 -> -38310000
A17: 16 | B17: 2 | C17: BWP | D17: A | E17: =B17&D17 -> 2A | F17: 28 | G17: 2 | H17: 1 | I17: 1 | J17: =C17 -> BWP | K17: 01 Juni 2026 | L17: 06 Juni 2026 | M17: Jumat | N17: Dua Puluh Sembilan | O17: Mei | P17: Dua Ribu Dua Puluh Enam | Q17: 29 Mei 2026 | Y17: Kelas | Z17: =ROUND(Z16/27,0) -> 19 | AD17: =Z16/Z17 -> 26.315789 | AE17: Kelas | AF17: =Z17 -> 19 | AJ17: =AF16/AF17 -> 26.315789 | AK17: Kelas | AL17: =Z17-AF17 -> 0 | AP17: =AL16/AL17 -> #DIV/0! | AQ17: =Z17 -> 19 | AR17: =AF17+AL17 -> 19 | AS17: =AR17-AQ17 -> 0 | CM17: TR | CN17: =AI9+AO9+AU9+BG9+BM9+BS9+BY9+CE9+CK9 -> 695130000 | CO17: K | CP17: =CN22 -> 175770000 | CQ17: =CP17/(105000) -> 1674 | CR17: =CQ17+50 -> 1724 | CV17: =20000*402*3 -> 24120000
A18: 17 | B18: 2 | C18: BWP | D18: B | E18: =B18&D18 -> 2B | F18: 28 | G18: 2 | H18: 1 | J18: =C18 -> BWP | K18: =IF(B16=B15,K17,"") -> 01 Juni 2026 | L18: =IF(B16=B15,L17,"") -> 06 Juni 2026 | M18: =IF(B16=B15,M17,"") -> Jumat | N18: =IF(B16=B15,N17,"") -> Dua Puluh Sembilan | O18: =IF(B16=B15,O17,"") -> Mei | P18: =IF(B16=B15,P17,"") -> Dua Ribu Dua Puluh Enam | Q18: =IF(B16=B15,Q17,"") -> 29 Mei 2026 | Y18: Inda | Z18: =Z17 -> 19 | AE18: Inda | AF18: =AF17 -> 19 | AK18: Inda | AL18: =Z18-AF18 -> 0 | AQ18: =Z18 -> 19 | AR18: =AF18+AL18 -> 19 | AS18: =AR18-AQ18 -> 0 | CM18: RP | CN18: =AI11+AO11+AU11+BG11+BM11+BS11+BY11+CE11+CK11+BA11 -> 24480000 | CO18: TR PM | CP18: =CN17 -> 695130000 | CQ18: =CP18/(170000*3) -> 1363 | CU18: =1375*3*430000 -> 1773750000 | CV18: =CU18-CP16 -> -70560000
A19: 18 | B19: 2 | C19: BWP | D19: C | E19: =B19&D19 -> 2C | F19: 28 | G19: 2 | H19: 1 | J19: =C19 -> BWP | K19: =IF(B19=B18,K18,"") -> 01 Juni 2026 | L19: =IF(B19=B18,L18,"") -> 06 Juni 2026 | M19: =IF(B19=B18,M18,"") -> Jumat | N19: =IF(B19=B18,N18,"") -> Dua Puluh Sembilan | O19: =IF(B19=B18,O18,"") -> Mei | P19: =IF(B19=B18,P18,"") -> Dua Ribu Dua Puluh Enam | Q19: =IF(B19=B18,Q18,"") -> 29 Mei 2026 | Y19: Panitia | Z19: =Z17*2 -> 38 | AE19: Panitia | AF19: =AF17*2 -> 38 | AK19: Panitia | AL19: =Z19-AF19 -> 0 | AQ19: =Z19 -> 38 | AR19: =AF19+AL19 -> 38 | AS19: =AR19-AQ19 -> 0 | CO19: TR STIS | CP19: =CN23 -> 284070000 | CQ19: =CP19/(170000) -> 1671 | CR19: =CQ19+50 -> 1721
A20: 19 | B20: 2 | C20: BWP | D20: D | E20: =B20&D20 -> 2D | F20: 28 | G20: 2 | H20: 1 | J20: =C20 -> BWP | K20: =IF(B20=B19,K19,"") -> 01 Juni 2026 | L20: =IF(B20=B19,L19,"") -> 06 Juni 2026 | M20: =IF(B20=B19,M19,"") -> Jumat | N20: =IF(B20=B19,N19,"") -> Dua Puluh Sembilan | O20: =IF(B20=B19,O19,"") -> Mei | P20: =IF(B20=B19,P19,"") -> Dua Ribu Dua Puluh Enam | Q20: =IF(B20=B19,Q19,"") -> 29 Mei 2026 | Y20: PJ | Z20: 1 | AE20: PJ | AF20: 1 | AK20: PJ | AL20: =Z20-AF20 -> 0 | AQ20: =Z20 -> 1 | AR20: =AF20+AL20 -> 1 | AS20: =AR20-AQ20 -> 0 | CM20: STIS | CO20: RP | CP20: =CN18+CN24 -> 34170000 | CQ20: =CP20/(170000) -> 201
A21: 20 | B21: 2 | C21: BWP | D21: E | E21: =B21&D21 -> 2E | F21: 28 | G21: 2 | H21: 1 | J21: =C21 -> BWP | K21: =IF(B21=B20,K20,"") -> 01 Juni 2026 | L21: =IF(B21=B20,L20,"") -> 06 Juni 2026 | M21: =IF(B21=B20,M20,"") -> Jumat | N21: =IF(B21=B20,N20,"") -> Dua Puluh Sembilan | O21: =IF(B21=B20,O20,"") -> Mei | P21: =IF(B21=B20,P20,"") -> Dua Ribu Dua Puluh Enam | Q21: =IF(B21=B20,Q20,"") -> 29 Mei 2026 | Y21: Total Konsumsi | Z21: =Z16+Z18+Z19+Z20 -> 558 | AA21: 105000 | AB21: 3 | AC21: =Z21*AA21*AB21 -> 175770000 | AE21: Total Konsumsi | AF21: =AF16+AF18+AF19+AF20 -> 558 | AG21: 105000 | AH21: 3 | AI21: =AF21*AG21*AH21 -> 175770000 | AK21: Total Konsumsi | AL21: =Z21-AF21 -> 0 | AM21: 105000 | AN21: 3 | AO21: =AL21*AM21*AN21 -> 0 | AQ21: =Z21 -> 558 | AR21: =AF21+AL21 -> 558 | AS21: =AR21-AQ21 -> 0 | AV21: =557*3 -> 1671 | CM21: INDA | CN21: =AF17*25*123000 -> 58425000
A22: 21 | B22: 2 | C22: BWP | D22: F | E22: =B22&D22 -> 2F | F22: 25 | G22: 2 | H22: 1 | J22: =C22 -> BWP | K22: =IF(B22=B21,K21,"") -> 01 Juni 2026 | L22: =IF(B22=B21,L21,"") -> 06 Juni 2026 | M22: =IF(B22=B21,M21,"") -> Jumat | N22: =IF(B22=B21,N21,"") -> Dua Puluh Sembilan | O22: =IF(B22=B21,O21,"") -> Mei | P22: =IF(B22=B21,P21,"") -> Dua Ribu Dua Puluh Enam | Q22: =IF(B22=B21,Q21,"") -> 29 Mei 2026 | Y22: Transport Peserta | Z22: =Z16+Z18+Z19 -> 557 | AA22: 170000 | AB22: 3 | AC22: =Z22*AA22*AB22 -> 284070000 | AE22: Transport Peserta | AF22: =AF16+AF18+AF19 -> 557 | AG22: 170000 | AH22: 3 | AI22: =AF22*AG22*AH22 -> 284070000 | AK22: Transport Peserta | AL22: =Z22-AF22 -> 0 | AM22: 170000 | AN22: 3 | AO22: =AL22*AM22*AN22 -> 0 | AQ22: =Z22 -> 557 | AR22: =AF22+AL22 -> 557 | AS22: =AR22-AQ22 -> 0 | AV22: =AV21+23*3 -> 1740 | CM22: K | CN22: =AI21 -> 175770000
A23: 22 | B23: 2 | C23: HARPER | D23: G | E23: =B23&D23 -> 2G | F23: 27 | G23: 2 | H23: 1 | J23: =C23 -> HARPER | K23: =IF(B21=B20,K22,"") -> 01 Juni 2026 | L23: =IF(B21=B20,L22,"") -> 06 Juni 2026 | M23: =IF(B21=B20,M22,"") -> Jumat | N23: =IF(B21=B20,N22,"") -> Dua Puluh Sembilan | O23: =IF(B21=B20,O22,"") -> Mei | P23: =IF(B21=B20,P22,"") -> Dua Ribu Dua Puluh Enam | Q23: =IF(B21=B20,Q22,"") -> 29 Mei 2026 | Y23: Perjadin PJ | Z23: =Z20 -> 1 | AA23: 210000 | AB23: 3 | AC23: =Z23*AA23*AB23 -> 630000 | AE23: Perjadin PJ | AF23: =AF20 -> 1 | AG23: 210000 | AH23: 3 | AI23: =AF23*AG23*AH23 -> 630000 | AK23: Perjadin PJ | AL23: =Z23-AF23 -> 0 | AM23: 210000 | AN23: 3 | AO23: =AL23*AM23*AN23 -> 0 | AQ23: =Z23 -> 1 | AR23: =AF23+AL23 -> 1 | AS23: =AR23-AQ23 -> 0 | CM23: TR | CN23: =AI22 -> 284070000
A24: 23 | B24: 2 | C24: HARPER | D24: H | E24: =B24&D24 -> 2H | F24: 27 | G24: 2 | H24: 1 | J24: =C24 -> HARPER | K24: =IF(B22=B21,K23,"") -> 01 Juni 2026 | L24: =IF(B22=B21,L23,"") -> 06 Juni 2026 | M24: =IF(B22=B21,M23,"") -> Jumat | N24: =IF(B22=B21,N23,"") -> Dua Puluh Sembilan | O24: =IF(B22=B21,O23,"") -> Mei | P24: =IF(B22=B21,P23,"") -> Dua Ribu Dua Puluh Enam | Q24: =IF(B22=B21,Q23,"") -> 29 Mei 2026 | Y24: Transport Role Playing | Z24: =Z17*3 -> 57 | AA24: 150000 | AB24: 1 | AC24: =Z24*AA24*AB24 -> 8550000 | AE24: Transport Role Playing | AF24: =AF17*3 -> 57 | AG24: 170000 | AH24: 1 | AI24: =AF24*AG24*AH24 -> 9690000 | AK24: Transport Role Playing | AL24: =Z24-AF24 -> 0 | AM24: 170000 | AN24: 1 | AO24: =AL24*AM24*AN24 -> 0 | AQ24: =Z24 -> 57 | AR24: =AF24+AL24 -> 57 | AS24: =AR24-AQ24 -> 0 | CM24: RP | CN24: =AI24 -> 9690000
A25: 24 | B25: 2 | C25: HARPER | D25: I | E25: =B25&D25 -> 2I | F25: 27 | G25: 2 | H25: 1 | J25: =C25 -> HARPER | K25: =IF(B23=B22,K24,"") -> 01 Juni 2026 | L25: =IF(B23=B22,L24,"") -> 06 Juni 2026 | M25: =IF(B23=B22,M24,"") -> Jumat | N25: =IF(B23=B22,N24,"") -> Dua Puluh Sembilan | O25: =IF(B23=B22,O24,"") -> Mei | P25: =IF(B23=B22,P24,"") -> Dua Ribu Dua Puluh Enam | Q25: =IF(B23=B22,Q24,"") -> 29 Mei 2026 | Y25: TOTAL STIS | AC25: =SUM(AC21:AC24) -> 469020000 | AE25: TOTAL STIS 1 | AI25: =SUM(AI21:AI24) -> 470160000 | AK25: TOTAL STIS 2 | AO25: =SUM(AO21:AO24) -> 0 | AQ25: =AC25 -> 469020000 | AR25: =AI25+AO25 -> 470160000 | AS25: =AR25-AQ25 -> 1140000
A26: 25 | B26: 2 | C26: HARPER | D26: J | E26: =B26&D26 -> 2J | F26: 27 | G26: 2 | H26: 1 | J26: =C26 -> HARPER | K26: =IF(B24=B23,K25,"") -> 01 Juni 2026 | L26: =IF(B24=B23,L25,"") -> 06 Juni 2026 | M26: =IF(B24=B23,M25,"") -> Jumat | N26: =IF(B24=B23,N25,"") -> Dua Puluh Sembilan | O26: =IF(B24=B23,O25,"") -> Mei | P26: =IF(B24=B23,P25,"") -> Dua Ribu Dua Puluh Enam | Q26: =IF(B24=B23,Q25,"") -> 29 Mei 2026
A27: 26 | B27: 2 | C27: PARK | D27: K | E27: =B27&D27 -> 2K | F27: 27 | G27: 2 | H27: 1 | J27: =C27 -> PARK | K27: =IF(B25=B24,K26,"") -> 01 Juni 2026 | L27: =IF(B25=B24,L26,"") -> 06 Juni 2026 | M27: =IF(B25=B24,M26,"") -> Jumat | N27: =IF(B25=B24,N26,"") -> Dua Puluh Sembilan | O27: =IF(B25=B24,O26,"") -> Mei | P27: =IF(B25=B24,P26,"") -> Dua Ribu Dua Puluh Enam | Q27: =IF(B25=B24,Q26,"") -> 29 Mei 2026 | Y27: GRAND TOTAL PELATIHAN PETUGAS | AC27: =AC12+AC25 -> 3115290000
A28: 27 | B28: 2 | C28: PARK | D28: L | E28: =B28&D28 -> 2L | F28: 27 | G28: 2 | H28: 1 | J28: =C28 -> PARK | K28: =IF(B26=B25,K27,"") -> 01 Juni 2026 | L28: =IF(B26=B25,L27,"") -> 06 Juni 2026 | M28: =IF(B26=B25,M27,"") -> Jumat | N28: =IF(B26=B25,N27,"") -> Dua Puluh Sembilan | O28: =IF(B26=B25,O27,"") -> Mei | P28: =IF(B26=B25,P27,"") -> Dua Ribu Dua Puluh Enam | Q28: =IF(B26=B25,Q27,"") -> 29 Mei 2026
A29: 28 | B29: 2 | C29: PARK | D29: M | E29: =B29&D29 -> 2M | F29: 27 | G29: 2 | H29: 1 | J29: =C29 -> PARK | K29: =IF(B27=B26,K28,"") -> 01 Juni 2026 | L29: =IF(B27=B26,L28,"") -> 06 Juni 2026 | M29: =IF(B27=B26,M28,"") -> Jumat | N29: =IF(B27=B26,N28,"") -> Dua Puluh Sembilan | O29: =IF(B27=B26,O28,"") -> Mei | P29: =IF(B27=B26,P28,"") -> Dua Ribu Dua Puluh Enam | Q29: =IF(B27=B26,Q28,"") -> 29 Mei 2026 | Z29: =Z21 -> 558 | AA29: 56000 | AB29: =Z29*AA29*3 -> 93744000
A30: 29 | B30: 2 | C30: PARK | D30: N | E30: =B30&D30 -> 2N | F30: 27 | G30: 2 | H30: 1 | J30: =C30 -> PARK | K30: =IF(B28=B27,K29,"") -> 01 Juni 2026 | L30: =IF(B28=B27,L29,"") -> 06 Juni 2026 | M30: =IF(B28=B27,M29,"") -> Jumat | N30: =IF(B28=B27,N29,"") -> Dua Puluh Sembilan | O30: =IF(B28=B27,O29,"") -> Mei | P30: =IF(B28=B27,P29,"") -> Dua Ribu Dua Puluh Enam | Q30: =IF(B28=B27,Q29,"") -> 29 Mei 2026 | Z30: =Z21 -> 558 | AA30: =24000*2 -> 48000 | AB30: =Z30*AA30*3 -> 80352000
A31: 30 | B31: 2 | C31: PARK | D31: O | E31: =B31&D31 -> 2O | F31: 27 | G31: 2 | H31: 1 | J31: =C31 -> PARK | K31: =IF(B29=B28,K30,"") -> 01 Juni 2026 | L31: =IF(B29=B28,L30,"") -> 06 Juni 2026 | M31: =IF(B29=B28,M30,"") -> Jumat | N31: =IF(B29=B28,N30,"") -> Dua Puluh Sembilan | O31: =IF(B29=B28,O30,"") -> Mei | P31: =IF(B29=B28,P30,"") -> Dua Ribu Dua Puluh Enam | Q31: =IF(B29=B28,Q30,"") -> 29 Mei 2026
A32: 31 | B32: 3 | C32: BWP | D32: A | E32: =B32&D32 -> 3A | F32: 28 | G32: 2 | H32: 1 | I32: 1 | J32: =C32 -> BWP | K32: 05 Juni 2026 | L32: 10 Juni 2026 | M32: Kamis | N32: Empat | O32: Juni | P32: Dua Ribu Dua Puluh Enam | Q32: 04 Juni 2026
A33: 32 | B33: 3 | C33: BWP | D33: B | E33: =B33&D33 -> 3B | F33: 28 | G33: 2 | H33: 1 | J33: =C33 -> BWP | K33: =IF(B28=B27,K32,"") -> 05 Juni 2026 | L33: =IF(B28=B27,L32,"") -> 10 Juni 2026 | M33: =IF(B28=B27,M32,"") -> Kamis | N33: =IF(B28=B27,N32,"") -> Empat | O33: =IF(B28=B27,O32,"") -> Juni | P33: =IF(B28=B27,P32,"") -> Dua Ribu Dua Puluh Enam | Q33: =IF(B28=B27,Q32,"") -> 04 Juni 2026
A34: 33 | B34: 3 | C34: BWP | D34: C | E34: =B34&D34 -> 3C | F34: 28 | G34: 2 | H34: 1 | J34: =C34 -> BWP | K34: =IF(B29=B28,K33,"") -> 05 Juni 2026 | L34: =IF(B29=B28,L33,"") -> 10 Juni 2026 | M34: =IF(B29=B28,M33,"") -> Kamis | N34: =IF(B29=B28,N33,"") -> Empat | O34: =IF(B29=B28,O33,"") -> Juni | P34: =IF(B29=B28,P33,"") -> Dua Ribu Dua Puluh Enam | Q34: =IF(B29=B28,Q33,"") -> 04 Juni 2026 | Z34: =500*3*150000 -> 225000000
A35: 34 | B35: 3 | C35: BWP | D35: D | E35: =B35&D35 -> 3D | F35: 28 | G35: 2 | H35: 1 | J35: =C35 -> BWP | K35: =IF(B30=B29,K34,"") -> 05 Juni 2026 | L35: =IF(B30=B29,L34,"") -> 10 Juni 2026 | M35: =IF(B30=B29,M34,"") -> Kamis | N35: =IF(B30=B29,N34,"") -> Empat | O35: =IF(B30=B29,O34,"") -> Juni | P35: =IF(B30=B29,P34,"") -> Dua Ribu Dua Puluh Enam | Q35: =IF(B30=B29,Q34,"") -> 04 Juni 2026
A36: 35 | B36: 3 | C36: BWP | D36: E | E36: =B36&D36 -> 3E | F36: 28 | G36: 2 | H36: 1 | J36: =C36 -> BWP | K36: =IF(B31=B30,K35,"") -> 05 Juni 2026 | L36: =IF(B31=B30,L35,"") -> 10 Juni 2026 | M36: =IF(B31=B30,M35,"") -> Kamis | N36: =IF(B31=B30,N35,"") -> Empat | O36: =IF(B31=B30,O35,"") -> Juni | P36: =IF(B31=B30,P35,"") -> Dua Ribu Dua Puluh Enam | Q36: =IF(B31=B30,Q35,"") -> 04 Juni 2026
A37: 36 | B37: 3 | C37: BWP | D37: F | E37: =B37&D37 -> 3F | F37: 25 | G37: 2 | H37: 1 | J37: =C37 -> BWP | K37: =IF(B35=B34,K36,"") -> 05 Juni 2026 | L37: =IF(B35=B34,L36,"") -> 10 Juni 2026 | M37: =IF(B35=B34,M36,"") -> Kamis | N37: =IF(B35=B34,N36,"") -> Empat | O37: =IF(B35=B34,O36,"") -> Juni | P37: =IF(B35=B34,P36,"") -> Dua Ribu Dua Puluh Enam | Q37: =IF(B35=B34,Q36,"") -> 04 Juni 2026
A38: 37 | B38: 3 | C38: HARPER | D38: G | E38: =B38&D38 -> 3G | F38: 27 | G38: 2 | H38: 1 | J38: =C38 -> HARPER | K38: =IF(B36=B35,K37,"") -> 05 Juni 2026 | L38: =IF(B36=B35,L37,"") -> 10 Juni 2026 | M38: =IF(B36=B35,M37,"") -> Kamis | N38: =IF(B36=B35,N37,"") -> Empat | O38: =IF(B36=B35,O37,"") -> Juni | P38: =IF(B36=B35,P37,"") -> Dua Ribu Dua Puluh Enam | Q38: =IF(B36=B35,Q37,"") -> 04 Juni 2026
A39: 38 | B39: 3 | C39: HARPER | D39: H | E39: =B39&D39 -> 3H | F39: 27 | G39: 2 | H39: 1 | J39: =C39 -> HARPER | K39: =IF(B37=B36,K38,"") -> 05 Juni 2026 | L39: =IF(B37=B36,L38,"") -> 10 Juni 2026 | M39: =IF(B37=B36,M38,"") -> Kamis | N39: =IF(B37=B36,N38,"") -> Empat | O39: =IF(B37=B36,O38,"") -> Juni | P39: =IF(B37=B36,P38,"") -> Dua Ribu Dua Puluh Enam | Q39: =IF(B37=B36,Q38,"") -> 04 Juni 2026
A40: 39 | B40: 3 | C40: HARPER | D40: I | E40: =B40&D40 -> 3I | F40: 27 | G40: 2 | H40: 1 | J40: =C40 -> HARPER | K40: =IF(B38=B37,K39,"") -> 05 Juni 2026 | L40: =IF(B38=B37,L39,"") -> 10 Juni 2026 | M40: =IF(B38=B37,M39,"") -> Kamis | N40: =IF(B38=B37,N39,"") -> Empat | O40: =IF(B38=B37,O39,"") -> Juni | P40: =IF(B38=B37,P39,"") -> Dua Ribu Dua Puluh Enam | Q40: =IF(B38=B37,Q39,"") -> 04 Juni 2026
...

Sheet PEGAWAI (REFERENSI)
A1: Widiastuti | B1: IV/a | C1: Pembina | D1: =C1&"/"&B1 -> Pembina/IV/a | E1: widiastuti3
A2: Habi Cahya Kumara | B2: IV/a | C2: Pembina | D2: =C2&"/"&B2 -> Pembina/IV/a | E2: habi
A3: Nuraliyah | B3: IV/a | C3: Pembina | D3: =C3&"/"&B3 -> Pembina/IV/a | E3: nuraliyah
A4: Dahlia Triyanti | B4: IV/a | C4: Pembina | D4: =C4&"/"&B4 -> Pembina/IV/a | E4: dahliatriyanti
A5: Hendriko Yanis | B5: III/d | C5: Penata Tk. I | D5: =C5&"/"&B5 -> Penata Tk. I/III/d | E5: hendriko
A6: Urip Kurniawan | B6: III/d | C6: Penata Tk. I | D6: =C6&"/"&B6 -> Penata Tk. I/III/d | E6: uripk
A7: Fauzia Miranti | B7: III/d | C7: Penata Tk. I | D7: =C7&"/"&B7 -> Penata Tk. I/III/d | E7: fauzia.miranti
A8: Armadi Setiawan | B8: III/d | C8: Penata Tk. I | D8: =C8&"/"&B8 -> Penata Tk. I/III/d | E8: armadis
A9: Pascoal Rocha Daconceicao | B9: III/c | C9: Penata | D9: =C9&"/"&B9 -> Penata/III/c | E9: pascoal
A10: Fitriyani | B10: III/d | C10: Penata Tk. I | D10: =C10&"/"&B10 -> Penata Tk. I/III/d | E10: fitriyani
A11: Nikodemus | B11: III/c | C11: Penata | D11: =C11&"/"&B11 -> Penata/III/c | E11: nikodemus
A12: Rizki Oktavian Wardhana | B12: III/c | C12: Penata | D12: =C12&"/"&B12 -> Penata/III/c | E12: rizki.ow
... A39: Nurhadi Fadilah | B39: I | C39: Golongan I | D39: =C39&"/"&B39 -> Golongan I/I | E39: nurhadifadil-pppk

Sheet PPL (ENTRI)
A1: No | B1: Gelombang | C1: Kelas | D1: Gel-Kelas | E1: TC | F1: Nomor Kontrak | G1: Nama Lengkap | H1: SOBAT ID | I1: Profesi | J1: Alamat | K1: Email | L1: No. Telepon | M1: Hari | N1: Tanggal | O1: Bulan | P1: Tahun | Q1: Tempat | R1: Tanggal Kontrak | S1: Tanggal | T1: Deadline | U1: Jumlah SLS | V1: Jumlah Muatan | W1: Keterangan Jika SLS Lebih dari 20 SLS/Sub SLS | X1: Keterangan Jika Muatan Kurang dari 650 | Y1: Keterangan Jika Muatan Lebih dari 700 | Z1: Keterangan Jika Lintas Kecamatan
A2: 0001 | D2: =B2&C2 | E2: =VLOOKUP(D2,'KELAS (REFERENSI)'!$E$1:$J$68,6,FALSE) -> #N/A | F2: ="PETUGAS."&A2&"/SPK/SE/PPL/3172/2026" -> PETUGAS.0001/SPK/SE/PPL/3172/2026 | H2: =VLOOKUP(G2,'MITRA (REFERENSI)'!$A:$Z,16,FALSE) -> #N/A | I2: =VLOOKUP(G2,'MITRA (REFERENSI)'!$A:$Z,25,FALSE) -> #N/A | J2: =VLOOKUP(G2,'MITRA (REFERENSI)'!$A:$Z,26,FALSE) -> #N/A | K2: =VLOOKUP(G2,'MITRA (REFERENSI)'!$A:$Z,15,FALSE) -> #N/A | L2: =VLOOKUP(G2,'MITRA (REFERENSI)'!$A:$Z,15,FALSE) -> #N/A | M2: =IF(B2=1,'KELAS (REFERENSI)'!M2,IF(B2=2,'KELAS (REFERENSI)'!M17,IF(B2=3,'KELAS (REFERENSI)'!M32,IF(B2=4,'KELAS (REFERENSI)'!M47,"")))) | N2: =IF(B2=1,'KELAS (REFERENSI)'!N2,IF(B2=2,'KELAS (REFERENSI)'!N17,IF(B2=3,'KELAS (REFERENSI)'!N32,IF(B2=4,'KELAS (REFERENSI)'!N47,"")))) | O2: =IF(B2=1,'KELAS (REFERENSI)'!O2,IF(B2=2,'KELAS (REFERENSI)'!O17,IF(B2=3,'KELAS (REFERENSI)'!O32,IF(B2=4,'KELAS (REFERENSI)'!O47,"")))) | P2: =IF(B2=1,'KELAS (REFERENSI)'!P2,IF(B2=2,'KELAS (REFERENSI)'!P17,IF(B2=3,'KELAS (REFERENSI)'!P32,IF(B2=4,'KELAS (REFERENSI)'!P47,"")))) | Q2: BPS Kota Jakarta Timur | R2: =IF(B2=1,'[1]KELAS (REF) 1080'!L2,IF(B2=2,'[1]KELAS (REF) 1080'!L15,IF(B2=3,'[1]KELAS (REF) 1080'!L45,""))) | S2: 15 Juni sampai dengan 31 Agustus 2026 | T2: 31 Agustus 2026
